

async function fn(){
    try{
        await a
    }catch(e){
        console.log('捕获到错误了')
    }
    
}
fn()

