### 一、错误处理 ###

#### 1.Error实例对象

   - JavaScript解析或运行时，一旦发生错误，引擎就会抛出一个错误对象。

   - **JavaScript 原生提供 Error 构造函数，所有抛出的错误都是这个构造函数的实例。**

     ```
     var err = new Error('出错了');
     err.message // "出错了"
     ```

     - 这个例子只是生成了一个实例对象err，并没有抛出错误，所以不会影响程序的运行。

   - **Error()构造函数接受一个参数，表示错误提示，可以从实例的message属性读到这个参数。抛出Error实例对象以后，整个程序就中断在发生错误的地方，不再往下执行。**

   - JavaScript语言标准只提到，Error实例对象必须有message属性，表示出错时的提示信息，没有提到其他属性。但大多数JavaScript引擎，对Error实例还提供name和stack属性，分别表示错误的名称和错误的堆栈，但它们是非标准的，不是每种实现都有。

#### 2.原生错误类型

  - **Error是基类型，其他错误类型都继承自该类型。因此，所有错误类型共享了一组相同的属性（错误对象中的方法全是默认的对象方法）**。Error类型的错误很少见，如果有也是浏览器抛出的，这个基类型的主要目的是供开发人员抛出自定义错误。

  - **这些原生错误类型都是实际的构造函数，旨在返回一个新的错误对象**

- **（1） EvalError对象 **

    - **EvalError类型的错误会在使用eval()函数而发生异常时被抛出，简单的说，如果没有把eval()当成函数调用，就会抛出错误。**该错误类型已经不再使用了，只是为了保证与以前代码兼容，才继续保留。

      ```
      new eval(); //抛出EvalError
      eval = foo; //抛出EvalError
      ```

    - 在实践中，浏览器不一定会在应该抛出错误时，就抛出EvalError。例如，Firefox 4+和IE8对第一种情况会抛出TypeError，而第二种情况会成功执行，不发生错误。

- **（2） RangeError对象 **

    - **在数值超过相应范围时触发**。

    - **主要有几种情况，一是数组长度为负数，二是Number对象的方法参数超出范围，以及函数堆栈超过最大值。**

    - 例如，在定义数组时，如果指定了数组不支持的项数(如-20或Number.MAX_VALUE)，就会触发这种错误。

      ```
      let items1 = new Array(-20)              //抛出RangeError
      let items2 = new Array(Number.MAX_VALUE) //抛出RangeError
      ```

      

- **（3） ReferenceError对象 **

    - **ReferenceError通常发生在我们尝试访问不存在的变量或函数时。这可能是由于拼写错误、作用域问题或者未声明的变量引起的。**

      ```
      let obj = x //在x并未声明的情况下抛出ReferenceError
      ```

    - **另一种触发场景是，将一个值分配给无法分配的对象，比如对函数的运行结果赋值。**

      ```
        // 等号左侧不是变量
      	console.log() = 1
      	// Uncaught ReferenceError: Invalid left-hand side in assignment
      ```

- **（4） SyntaxError对象 **

    - **SyntaxError 表示语法错误**。这些错误是最容易修复的错误之一，因为它们表明代码语法中存在错误。由于 JavaScript 是一种解释而非编译的脚本语言，因此当应用程序执行包含错误的脚本时会抛出这些错误。在编译语言的情况下，此类错误在编译期间被识别。因此，在修复这些问题之前，不会创建应用程序二进制文件。

    - **SyntaxError 发生的一些常见原因是：**

      - 缺少引号

      - 缺少右括号

      - 大括号或其他字符对齐不当

        ```
        // 变量名错误
        var 1a;
        // Uncaught SyntaxError: Invalid or unexpected token
        
        // 缺少括号
        console.log 'hello');
        // Uncaught SyntaxError: Unexpected string
        ```

        

- **（5）TypeError对象 **

   - **TypeError对象是变量或参数不是预期类型时发生的错误。比如，对字符串、布尔值、数值等原始类型的值使用new命令，就会抛出这种错误，因为new命令的参数应该是一个构造函数。**

     ```
     new 123
     	// Uncaught TypeError: 123 is not a constructor
     var obj = {};
     obj.unknownMethod()
     // Uncaught TypeError: obj.unknownMethod is not a function
     ```

- **（6）URIError对象 **

   - **URIError对象是 URI 相关函数的参数不正确时抛出的错误，主要涉及encodeURI()、decodeURI()、encodeURIComponent()、decodeURIComponent()、escape()和unescape()这六个函数。**

     ```
     decodeURI('%2')
     // URIError: URI malformed
     ```

     

- **总结**

  - 以上这6种派生错误，连同原始的Error对象，都是构造函数。开发者可以使用它们，手动生成错误对象的实例。这些构造函数都接受一个参数，代表错误提示信息

    ```
    var err1 = new Error('出错了！');
    var err2 = new RangeError('出错了，变量超出有效范围！');
    var err3 = new TypeError('出错了，变量类型无效！');
    
    err1.message // "出错了！"
    err2.message // "出错了，变量超出有效范围！"
    err3.message // "出错了，变量类型无效！"
    ```

#### 3.自定义错误 

- **除了 JavaScript 原生提供的七种错误对象，还可以定义自己的错误对象。 **

  ```
  function UserError(message) {
    this.message = message || '默认信息';
    this.name = 'UserError';
  }
  
  UserError.prototype = new Error();
  UserError.prototype.constructor = UserError;
  ```

  

- 上面代码自定义一个错误对象UserError，让它继承Error对象。然后，就可以生成这种自定义类型的错误了。

  ```
  new UserError('这是自定义的错误！');
  ```

  

#### 4. throw 语句 

- **throw语句的作用是手动中断程序执行，抛出一个错误。**

  ```
  var x = -1;
  
  if (x <= 0) {
    throw new Error('x 必须为正数');
  }
  // Uncaught Error: x 必须为正数
  ```

  

- **throw也可以抛出自定义错误。**

  ```
  function UserError(message) {
    this.message = message || '默认信息';
    this.name = 'UserError';
  }
  
  throw new UserError('出错了！');
  // Uncaught UserError {message: "出错了！", name: "UserError"}
  ```

  - 上面代码中，throw抛出的是一个UserError实例。

- **实际上，throw可以抛出任何类型的值。也就是说，它的参数可以是任何值。**

  	// 抛出一个字符串
  	throw 'Error！';
  	// Uncaught Error！
  	
  	// 抛出一个数值
  	throw 42;
  	// Uncaught 42
  	
  	// 抛出一个布尔值
  	throw true;
  	// Uncaught true
  	
  	// 抛出一个对象
  	throw {
  	  toString: function () {
  	    return 'Error!';
  	  }
  	};
  	// Uncaught {toString: ƒ}

- **对于 JavaScript 引擎来说，遇到throw语句，程序就中止了。引擎会接收到throw抛出的信息，可能是一个错误实例，也可能是其他类型的值。**

#### 5.try...catch 结构 

- 一旦发生错误，程序就中止执行了。JavaScript 提供了try...catch结构，允许对错误进行处理，选择是否往下执行。

- **如果 catch 不存在的话 程序会中止 起不到拦截错误的作用**

  ```
  try {
    throw new Error('出错了!');
  } catch (e) {
    console.log(e.name + ": " + e.message);
    console.log(e.stack);
  }
  // Error: 出错了!
  //   at <anonymous>:3:9
  //   ...
  ```


- 上面代码中，try代码块抛出错误（上例用的是throw语句），JavaScript 引擎就立即把代码的执行，转到catch代码块，或者说错误被catch代码块捕获了。catch接受一个参数，表示try代码块抛出的值。

- **catch代码块捕获错误之后，程序不会中断，会按照正常流程继续执行下去。**
  	

  	try {
  	  throw "出错了";
  	} catch (e) {
  	  console.log(111);
  	}
  	console.log(222);
  	// 111
  	// 222

- **catch代码块之中，还可以再抛出错误，甚至使用嵌套的try...catch结构。**

  	var n = 100;
  	
  	try {
  	  throw n;
  	} catch (e) {
  	  if (e <= 50) {
  	    // ...
  	  } else {
  	    throw e;
  	  }
  	}
  	// Uncaught 100

   - 上面代码中，catch代码之中又抛出了一个错误。

- **为了捕捉不同类型的错误，catch代码块之中可以加入判断语句**

  	try {
  	  foo.bar();
  	} catch (e) {
  	  if (e instanceof EvalError) {
  	    console.log(e.name + ": " + e.message);
  	  } else if (e instanceof RangeError) {
  	    console.log(e.name + ": " + e.message);
  	  }
  	  // ...
  	}

#### 6.finally 代码块 	

- **try...catch结构允许在最后添加一个finally代码块，表示不管是否出现错误，都必须在最后运行的语句。**

- **但是这里有一个注意点。是先执行 finally， 再报错的。**

- **理解：因为 throw err 之后程序不会再运行 所以会先执行完 finally 里面的代码之后抛出错误**

  	function cleansUp() {
  	  try {
  	    throw new Error('出错了……');
  	    console.log('此行不会执行');
  	  } finally {
  	    console.log('完成清理工作');
  	  }
  	}
  	
  	cleansUp()
  	
  	// 完成清理工作
  	// Uncaught Error: 出错了……
  	//    at cleansUp (<anonymous>:3:11)
  	//    at <anonymous>:10:1


- 上面代码中，由于没有catch语句块，一旦发生错误，代码就会中断执行。中断执行之前，会先执行finally代码块，然后再向用户提示报错信息。

  	function idle(x) {
  	  try {
  	    console.log(x);
  	    return 'result';
  	  } finally {
  	    console.log('FINALLY');
  	  }
  	}
  	
  	idle('hello')
  	// hello
  	// FINALLY

- 上面代码中，try代码块没有发生错误，而且里面还包括return语句，但是finally代码块依然会执行。而且，这个函数的返回值还是result。

  	var count = 0;
  	function countUp() {
  	  try {
  	    return count;
  	  } finally {
  	    count++;
  	  }
  	}
  	
  	countUp()
  	// 0
  	count
  	// 1

- 上面代码说明，return语句的执行是排在finally代码之前，只是等finally代码执行完毕后才返回。
  	
  	

  	function f() {
  	  try {
  	    console.log(0);
  	    throw 'bug';
  	  } catch(e) {
  	    console.log(1);
  	    return true; // 这句原本会延迟到 finally 代码块结束再执行
  	    console.log(2); // 不会运行
  	  } finally {
  	    console.log(3);
  	    return false; // 这句会覆盖掉前面那句 return
  	    console.log(4); // 不会运行
  	  }
  	
  	  console.log(5); // 不会运行
  	}
  	
  	var result = f();
  	// 0
  	// 1
  	// 3
  	
  	result
  	// false

- 上面代码中，catch代码块结束执行之前，会先执行finally代码块。

- **catch代码块之中，触发转入finally代码块的标志，不仅有return语句，还有throw语句。**

  	function f() {
  	  try {
  	    throw '出错了！';
  	  } catch(e) {
  	    console.log('捕捉到内部错误');
  	    throw e; // 这句原本会等到finally结束再执行
  	  } finally {
  	    return false; // 直接返回
  	  }
  	}
  	
  	try {
  	  f();
  	} catch(e) {
  	  // 此处不会执行
  	  console.log('caught outer "bogus"');
  	}
  	
  	//  捕捉到内部错误

   - 上面代码中，进入catch代码块之后，一遇到throw语句，就会去执行finally代码块，其中有return false语句，因此就直接返回了，不再会回去执行catch代码块剩下的部分了。

- **try代码块内部，还可以再使用try代码块。**

  	try {
  	  try {
  	    consle.log('Hello world!'); // 报错
  	  }
  	  finally {
  	    console.log('Finally');
  	  }
  	  console.log('Will I run?');
  	} catch(error) {
  	  console.error(error.message);
  	}
  	// Finally
  	// consle is not defined

####  ####